Workbook

Sheet MENU

Sheet ORÇAMENTO
C2: CUSTO TOTAL | D2: PREÇO SUGERIDO | E2: PREÇO A TRABALHAR | F2: PORCENTAGEM
C3: =SUM(D7:D1014) -> 0 | D3: =SUM(E7:E1014) -> 0 | E3: =SUM(G7:G1014) -> 0 | F3: 1
C4: MARKUP MEDIO | D4: =IF(D3=0,"",SUM(F7:F1014)/COUNT(F7:F1014))
A6: MARCA | B6: PRODUTO | C6: QUANTIDADE | D6: CUSTO | E6: PREÇO SUGERIDO | F6: MARKUP | G6: PREÇO A TRABALHAR
D7: =IF($B7="","",SUM(VLOOKUP($B7,DADOS!$C$2:$I1014,4,0)*$C7)) | E7: =IF($B7="","",SUM(VLOOKUP($B7,DADOS!$C$2:$I1014,6,0)*$C7)) | F7: =IF($E7="","",(VLOOKUP($B7,DADOS!$C$2:$I1014,7,0))) | G7: =IF(D7="","",D7*$F$3+D7)
A8: =IF($B8="","",VLOOKUP($B8,DADOS!$C$2:$I1014,2,0)) | D8: =IF($B8="","",SUM(VLOOKUP($B8,DADOS!$C$2:$I1014,4,0)*$C8)) | E8: =IF($B8="","",SUM(VLOOKUP($B8,DADOS!$C$2:$I1014,6,0)*$C8)) | F8: =IF($E8="","",(VLOOKUP($B8,DADOS!$C$2:$I1014,7,0))) | G8: =IF(D8="","",D8*$F$3+D8)
A9: =IF($B9="","",VLOOKUP($B9,DADOS!$C$2:$I1014,2,0)) | D9: =IF($B9="","",SUM(VLOOKUP($B9,DADOS!$C$2:$I1014,4,0)*$C9)) | E9: =IF($B9="","",SUM(VLOOKUP($B9,DADOS!$C$2:$I1014,6,0)*$C9)) | F9: =IF($E9="","",(VLOOKUP($B9,DADOS!$C$2:$I1014,7,0))) | G9: =IF(D9="","",D9*$F$3+D9)
A10: =IF($B10="","",VLOOKUP($B10,DADOS!$C$2:$I1014,2,0)) | D10: =IF($B10="","",SUM(VLOOKUP($B10,DADOS!$C$2:$I1014,4,0)*$C10)) | E10: =IF($B10="","",SUM(VLOOKUP($B10,DADOS!$C$2:$I1014,6,0)*$C10)) | F10: =IF($E10="","",(VLOOKUP($B10,DADOS!$C$2:$I1014,7,0))) | G10: =IF(D10="","",D10*$F$3+D10)
A11: =IF($B11="","",VLOOKUP($B11,DADOS!$C$2:$I1014,2,0)) | D11: =IF($B11="","",SUM(VLOOKUP($B11,DADOS!$C$2:$I1014,4,0)*$C11)) | E11: =IF($B11="","",SUM(VLOOKUP($B11,DADOS!$C$2:$I1014,6,0)*$C11)) | F11: =IF($E11="","",(VLOOKUP($B11,DADOS!$C$2:$I1014,7,0))) | G11: =IF(D11="","",D11*$F$3+D11)
A12: =IF($B12="","",VLOOKUP($B12,DADOS!$C$2:$I1014,2,0)) | D12: =IF($B12="","",SUM(VLOOKUP($B12,DADOS!$C$2:$I1014,4,0)*$C12)) | E12: =IF($B12="","",SUM(VLOOKUP($B12,DADOS!$C$2:$I1014,6,0)*$C12)) | F12: =IF($E12="","",(VLOOKUP($B12,DADOS!$C$2:$I1014,7,0))) | G12: =IF(D12="","",D12*$F$3+D12)
A13: =IF($B13="","",VLOOKUP($B13,DADOS!$C$2:$I1014,2,0)) | D13: =IF($B13="","",SUM(VLOOKUP($B13,DADOS!$C$2:$I1014,4,0)*$C13)) | E13: =IF($B13="","",SUM(VLOOKUP($B13,DADOS!$C$2:$I1014,6,0)*$C13)) | F13: =IF($E13="","",(VLOOKUP($B13,DADOS!$C$2:$I1014,7,0))) | G13: =IF(D13="","",D13*$F$3+D13)
A14: =IF($B14="","",VLOOKUP($B14,DADOS!$C$2:$I1014,2,0)) | D14: =IF($B14="","",SUM(VLOOKUP($B14,DADOS!$C$2:$I1014,4,0)*$C14)) | E14: =IF($B14="","",SUM(VLOOKUP($B14,DADOS!$C$2:$I1014,6,0)*$C14)) | F14: =IF($E14="","",(VLOOKUP($B14,DADOS!$C$2:$I1014,7,0))) | G14: =IF(D14="","",D14*$F$3+D14)
A15: =IF($B15="","",VLOOKUP($B15,DADOS!$C$2:$I1014,2,0)) | D15: =IF($B15="","",SUM(VLOOKUP($B15,DADOS!$C$2:$I1014,4,0)*$C15)) | E15: =IF($B15="","",SUM(VLOOKUP($B15,DADOS!$C$2:$I1014,6,0)*$C15)) | F15: =IF($E15="","",(VLOOKUP($B15,DADOS!$C$2:$I1014,7,0))) | G15: =IF(D15="","",D15*$F$3+D15)
A16: =IF($B16="","",VLOOKUP($B16,DADOS!$C$2:$I1014,2,0)) | D16: =IF($B16="","",SUM(VLOOKUP($B16,DADOS!$C$2:$I1014,4,0)*$C16)) | E16: =IF($B16="","",SUM(VLOOKUP($B16,DADOS!$C$2:$I1014,6,0)*$C16)) | F16: =IF($E16="","",(VLOOKUP($B16,DADOS!$C$2:$I1014,7,0))) | G16: =IF(D16="","",D16*$F$3+D16)
A17: =IF($B17="","",VLOOKUP($B17,DADOS!$C$2:$I1014,2,0)) | D17: =IF($B17="","",SUM(VLOOKUP($B17,DADOS!$C$2:$I1014,4,0)*$C17)) | E17: =IF($B17="","",SUM(VLOOKUP($B17,DADOS!$C$2:$I1014,6,0)*$C17)) | F17: =IF($E17="","",(VLOOKUP($B17,DADOS!$C$2:$I1014,7,0))) | G17: =IF(D17="","",D17*$F$3+D17)
A18: =IF($B18="","",VLOOKUP($B18,DADOS!$C$2:$I1014,2,0)) | D18: =IF($B18="","",SUM(VLOOKUP($B18,DADOS!$C$2:$I1014,4,0)*$C18)) | E18: =IF($B18="","",SUM(VLOOKUP($B18,DADOS!$C$2:$I1014,6,0)*$C18)) | F18: =IF($E18="","",(VLOOKUP($B18,DADOS!$C$2:$I1014,7,0))) | G18: =IF(D18="","",D18*$F$3+D18)
A19: =IF($B19="","",VLOOKUP($B19,DADOS!$C$2:$I1014,2,0)) | D19: =IF($B19="","",SUM(VLOOKUP($B19,DADOS!$C$2:$I1014,4,0)*$C19)) | E19: =IF($B19="","",SUM(VLOOKUP($B19,DADOS!$C$2:$I1014,6,0)*$C19)) | F19: =IF($E19="","",(VLOOKUP($B19,DADOS!$C$2:$I1014,7,0))) | G19: =IF(D19="","",D19*$F$3+D19)
A20: =IF($B20="","",VLOOKUP($B20,DADOS!$C$2:$I1014,2,0)) | D20: =IF($B20="","",SUM(VLOOKUP($B20,DADOS!$C$2:$I1014,4,0)*$C20)) | E20: =IF($B20="","",SUM(VLOOKUP($B20,DADOS!$C$2:$I1014,6,0)*$C20)) | F20: =IF($E20="","",(VLOOKUP($B20,DADOS!$C$2:$I1014,7,0))) | G20: =IF(D20="","",D20*$F$3+D20)
A21: =IF($B21="","",VLOOKUP($B21,DADOS!$C$2:$I1014,2,0)) | D21: =IF($B21="","",SUM(VLOOKUP($B21,DADOS!$C$2:$I1014,4,0)*$C21)) | E21: =IF($B21="","",SUM(VLOOKUP($B21,DADOS!$C$2:$I1014,6,0)*$C21)) | F21: =IF($E21="","",(VLOOKUP($B21,DADOS!$C$2:$I1014,7,0))) | G21: =IF(D21="","",D21*$F$3+D21)
A22: =IF($B22="","",VLOOKUP($B22,DADOS!$C$2:$I1014,2,0)) | D22: =IF($B22="","",SUM(VLOOKUP($B22,DADOS!$C$2:$I1014,4,0)*$C22)) | E22: =IF($B22="","",SUM(VLOOKUP($B22,DADOS!$C$2:$I1014,6,0)*$C22)) | F22: =IF($E22="","",(VLOOKUP($B22,DADOS!$C$2:$I1014,7,0))) | G22: =IF(D22="","",D22*$F$3+D22)
A23: =IF($B23="","",VLOOKUP($B23,DADOS!$C$2:$I1014,2,0)) | D23: =IF($B23="","",SUM(VLOOKUP($B23,DADOS!$C$2:$I1014,4,0)*$C23)) | E23: =IF($B23="","",SUM(VLOOKUP($B23,DADOS!$C$2:$I1014,6,0)*$C23)) | F23: =IF($E23="","",(VLOOKUP($B23,DADOS!$C$2:$I1014,7,0))) | G23: =IF(D23="","",D23*$F$3+D23)
A24: =IF($B24="","",VLOOKUP($B24,DADOS!$C$2:$I1014,2,0)) | D24: =IF($B24="","",SUM(VLOOKUP($B24,DADOS!$C$2:$I1014,4,0)*$C24)) | E24: =IF($B24="","",SUM(VLOOKUP($B24,DADOS!$C$2:$I1014,6,0)*$C24)) | F24: =IF($E24="","",(VLOOKUP($B24,DADOS!$C$2:$I1014,7,0))) | G24: =IF(D24="","",D24*$F$3+D24)
A25: =IF($B25="","",VLOOKUP($B25,DADOS!$C$2:$I1014,2,0)) | D25: =IF($B25="","",SUM(VLOOKUP($B25,DADOS!$C$2:$I1014,4,0)*$C25)) | E25: =IF($B25="","",SUM(VLOOKUP($B25,DADOS!$C$2:$I1014,6,0)*$C25)) | F25: =IF($E25="","",(VLOOKUP($B25,DADOS!$C$2:$I1014,7,0))) | G25: =IF(D25="","",D25*$F$3+D25)
A26: =IF($B26="","",VLOOKUP($B26,DADOS!$C$2:$I1014,2,0)) | D26: =IF($B26="","",SUM(VLOOKUP($B26,DADOS!$C$2:$I1014,4,0)*$C26)) | E26: =IF($B26="","",SUM(VLOOKUP($B26,DADOS!$C$2:$I1014,6,0)*$C26)) | F26: =IF($E26="","",(VLOOKUP($B26,DADOS!$C$2:$I1014,7,0))) | G26: =IF(D26="","",D26*$F$3+D26)
A27: =IF($B27="","",VLOOKUP($B27,DADOS!$C$2:$I1014,2,0)) | D27: =IF($B27="","",SUM(VLOOKUP($B27,DADOS!$C$2:$I1014,4,0)*$C27)) | E27: =IF($B27="","",SUM(VLOOKUP($B27,DADOS!$C$2:$I1014,6,0)*$C27)) | F27: =IF($E27="","",(VLOOKUP($B27,DADOS!$C$2:$I1014,7,0))) | G27: =IF(D27="","",D27*$F$3+D27)
A28: =IF($B28="","",VLOOKUP($B28,DADOS!$C$2:$I1014,2,0)) | D28: =IF($B28="","",SUM(VLOOKUP($B28,DADOS!$C$2:$I1014,4,0)*$C28)) | E28: =IF($B28="","",SUM(VLOOKUP($B28,DADOS!$C$2:$I1014,6,0)*$C28)) | F28: =IF($E28="","",(VLOOKUP($B28,DADOS!$C$2:$I1014,7,0))) | G28: =IF(D28="","",D28*$F$3+D28)
A29: =IF($B29="","",VLOOKUP($B29,DADOS!$C$2:$I1014,2,0)) | D29: =IF($B29="","",SUM(VLOOKUP($B29,DADOS!$C$2:$I1014,4,0)*$C29)) | E29: =IF($B29="","",SUM(VLOOKUP($B29,DADOS!$C$2:$I1014,6,0)*$C29)) | F29: =IF($E29="","",(VLOOKUP($B29,DADOS!$C$2:$I1014,7,0))) | G29: =IF(D29="","",D29*$F$3+D29)
A30: =IF($B30="","",VLOOKUP($B30,DADOS!$C$2:$I1014,2,0)) | D30: =IF($B30="","",SUM(VLOOKUP($B30,DADOS!$C$2:$I1014,4,0)*$C30)) | E30: =IF($B30="","",SUM(VLOOKUP($B30,DADOS!$C$2:$I1014,6,0)*$C30)) | F30: =IF($E30="","",(VLOOKUP($B30,DADOS!$C$2:$I1014,7,0))) | G30: =IF(D30="","",D30*$F$3+D30)
A31: =IF($B31="","",VLOOKUP($B31,DADOS!$C$2:$I1014,2,0)) | D31: =IF($B31="","",SUM(VLOOKUP($B31,DADOS!$C$2:$I1014,4,0)*$C31)) | E31: =IF($B31="","",SUM(VLOOKUP($B31,DADOS!$C$2:$I1014,6,0)*$C31)) | F31: =IF($E31="","",(VLOOKUP($B31,DADOS!$C$2:$I1014,7,0))) | G31: =IF(D31="","",D31*$F$3+D31)
A32: =IF($B32="","",VLOOKUP($B32,DADOS!$C$2:$I1014,2,0)) | D32: =IF($B32="","",SUM(VLOOKUP($B32,DADOS!$C$2:$I1014,4,0)*$C32)) | E32: =IF($B32="","",SUM(VLOOKUP($B32,DADOS!$C$2:$I1014,6,0)*$C32)) | F32: =IF($E32="","",(VLOOKUP($B32,DADOS!$C$2:$I1014,7,0))) | G32: =IF(D32="","",D32*$F$3+D32)
A33: =IF($B33="","",VLOOKUP($B33,DADOS!$C$2:$I1014,2,0)) | D33: =IF($B33="","",SUM(VLOOKUP($B33,DADOS!$C$2:$I1014,4,0)*$C33)) | E33: =IF($B33="","",SUM(VLOOKUP($B33,DADOS!$C$2:$I1014,6,0)*$C33)) | F33: =IF($E33="","",(VLOOKUP($B33,DADOS!$C$2:$I1014,7,0))) | G33: =IF(D33="","",D33*$F$3+D33)
A34: =IF($B34="","",VLOOKUP($B34,DADOS!$C$2:$I1014,2,0)) | D34: =IF($B34="","",SUM(VLOOKUP($B34,DADOS!$C$2:$I1014,4,0)*$C34)) | E34: =IF($B34="","",SUM(VLOOKUP($B34,DADOS!$C$2:$I1014,6,0)*$C34)) | F34: =IF($E34="","",(VLOOKUP($B34,DADOS!$C$2:$I1014,7,0))) | G34: =IF(D34="","",D34*$F$3+D34)
A35: =IF($B35="","",VLOOKUP($B35,DADOS!$C$2:$I1014,2,0)) | D35: =IF($B35="","",SUM(VLOOKUP($B35,DADOS!$C$2:$I1014,4,0)*$C35)) | E35: =IF($B35="","",SUM(VLOOKUP($B35,DADOS!$C$2:$I1014,6,0)*$C35)) | F35: =IF($E35="","",(VLOOKUP($B35,DADOS!$C$2:$I1014,7,0))) | G35: =IF(D35="","",D35*$F$3+D35)
A36: =IF($B36="","",VLOOKUP($B36,DADOS!$C$2:$I1014,2,0)) | D36: =IF($B36="","",SUM(VLOOKUP($B36,DADOS!$C$2:$I1014,4,0)*$C36)) | E36: =IF($B36="","",SUM(VLOOKUP($B36,DADOS!$C$2:$I1014,6,0)*$C36)) | F36: =IF($E36="","",(VLOOKUP($B36,DADOS!$C$2:$I1014,7,0))) | G36: =IF(D36="","",D36*$F$3+D36)
A37: =IF($B37="","",VLOOKUP($B37,DADOS!$C$2:$I1014,2,0)) | D37: =IF($B37="","",SUM(VLOOKUP($B37,DADOS!$C$2:$I1014,4,0)*$C37)) | E37: =IF($B37="","",SUM(VLOOKUP($B37,DADOS!$C$2:$I1014,6,0)*$C37)) | F37: =IF($E37="","",(VLOOKUP($B37,DADOS!$C$2:$I1014,7,0))) | G37: =IF(D37="","",D37*$F$3+D37)
A38: =IF($B38="","",VLOOKUP($B38,DADOS!$C$2:$I1014,2,0)) | D38: =IF($B38="","",SUM(VLOOKUP($B38,DADOS!$C$2:$I1014,4,0)*$C38)) | E38: =IF($B38="","",SUM(VLOOKUP($B38,DADOS!$C$2:$I1014,6,0)*$C38)) | F38: =IF($E38="","",(VLOOKUP($B38,DADOS!$C$2:$I1014,7,0))) | G38: =IF(D38="","",D38*$F$3+D38)
A39: =IF($B39="","",VLOOKUP($B39,DADOS!$C$2:$I1014,2,0)) | D39: =IF($B39="","",SUM(VLOOKUP($B39,DADOS!$C$2:$I1014,4,0)*$C39)) | E39: =IF($B39="","",SUM(VLOOKUP($B39,DADOS!$C$2:$I1014,6,0)*$C39)) | F39: =IF($E39="","",(VLOOKUP($B39,DADOS!$C$2:$I1014,7,0))) | G39: =IF(D39="","",D39*$F$3+D39)
A40: =IF($B40="","",VLOOKUP($B40,DADOS!$C$2:$I1014,2,0)) | D40: =IF($B40="","",SUM(VLOOKUP($B40,DADOS!$C$2:$I1014,4,0)*$C40)) | E40: =IF($B40="","",SUM(VLOOKUP($B40,DADOS!$C$2:$I1014,6,0)*$C40)) | F40: =IF($E40="","",(VLOOKUP($B40,DADOS!$C$2:$I1014,7,0))) | G40: =IF(D40="","",D40*$F$3+D40)
A41: =IF($B41="","",VLOOKUP($B41,DADOS!$C$2:$I1014,2,0)) | D41: =IF($B41="","",SUM(VLOOKUP($B41,DADOS!$C$2:$I1014,4,0)*$C41)) | E41: =IF($B41="","",SUM(VLOOKUP($B41,DADOS!$C$2:$I1014,6,0)*$C41)) | F41: =IF($E41="","",(VLOOKUP($B41,DADOS!$C$2:$I1014,7,0))) | G41: =IF(D41="","",D41*$F$3+D41)
A42: =IF($B42="","",VLOOKUP($B42,DADOS!$C$2:$I1014,2,0)) | D42: =IF($B42="","",SUM(VLOOKUP($B42,DADOS!$C$2:$I1014,4,0)*$C42)) | E42: =IF($B42="","",SUM(VLOOKUP($B42,DADOS!$C$2:$I1014,6,0)*$C42)) | F42: =IF($E42="","",(VLOOKUP($B42,DADOS!$C$2:$I1014,7,0))) | G42: =IF(D42="","",D42*$F$3+D42)
...

Sheet DADOS
C1: PRODUTOS | D1: MARCA | E1: % | F1: CUSTO | G1: CUSTO TOTAL | H1: PREÇO SUGERIDO | I1: MARGEM
C2: =IFERROR(__xludf.DUMMYFUNCTION("IMPORTRANGE(""https://docs.google.com/spreadsheets/d/1DsdxsrBJOk75sDGmXMsLLa15LHA7JaMlvKBZACG-RHY/edit?gid=1280887965#gid=1280887965"",""TESTE!B2"")"),"AAT AC-1 G2") -> AAT AC-1 G2 | D2: =IFERROR(__xludf.DUMMYFUNCTION("IMPORTRANGE(""https://docs.google.com/spreadsheets/d/1DsdxsrBJOk75sDGmXMsLLa15LHA7JaMlvKBZACG-RHY/edit?gid=1280887965#gid=1280887965"",""TESTE!A2"")"),"AAT") -> AAT | E2: 0 | F2: 0 | G2: 0 | H2: =IFERROR(__xludf.DUMMYFUNCTION("IMPORTRANGE(""https://docs.google.com/spreadsheets/d/1DsdxsrBJOk75sDGmXMsLLa15LHA7JaMlvKBZACG-RHY/edit?gid=1280887965#gid=1280887965"",""TESTE!D2"")"),3640.0) -> 3640 | I2: =IF(G2>0,(H2-G2)/G2,IF(H2>0,0,0)) -> 0
C3: =IFERROR(__xludf.DUMMYFUNCTION("IMPORTRANGE(""https://docs.google.com/spreadsheets/d/1DsdxsrBJOk75sDGmXMsLLa15LHA7JaMlvKBZACG-RHY/edit?gid=1280887965#gid=1280887965"",""TESTE!B3"")"),"AAT AC-2 G2") -> AAT AC-2 G2 | D3: =IFERROR(__xludf.DUMMYFUNCTION("IMPORTRANGE(""https://docs.google.com/spreadsheets/d/1DsdxsrBJOk75sDGmXMsLLa15LHA7JaMlvKBZACG-RHY/edit?gid=1280887965#gid=1280887965"",""TESTE!A3"")"),"AAT") -> AAT | E3: 0 | F3: 0 | G3: 0 | H3: =IFERROR(__xludf.DUMMYFUNCTION("IMPORTRANGE(""https://docs.google.com/spreadsheets/d/1DsdxsrBJOk75sDGmXMsLLa15LHA7JaMlvKBZACG-RHY/edit?gid=1280887965#gid=1280887965"",""TESTE!D3"")"),2150.0) -> 2150 | I3: =IF(G3>0,(H3-G3)/G3,IF(H3>0,0,0)) -> 0
C4: =IFERROR(__xludf.DUMMYFUNCTION("IMPORTRANGE(""https://docs.google.com/spreadsheets/d/1DsdxsrBJOk75sDGmXMsLLa15LHA7JaMlvKBZACG-RHY/edit?gid=1280887965#gid=1280887965"",""TESTE!B4"")"),"AAT BTA-1 G2") -> AAT BTA-1 G2 | D4: =IFERROR(__xludf.DUMMYFUNCTION("IMPORTRANGE(""https://docs.google.com/spreadsheets/d/1DsdxsrBJOk75sDGmXMsLLa15LHA7JaMlvKBZACG-RHY/edit?gid=1280887965#gid=1280887965"",""TESTE!A4"")"),"AAT") -> AAT | E4: 0 | F4: 0 | G4: 0 | H4: =IFERROR(__xludf.DUMMYFUNCTION("IMPORTRANGE(""https://docs.google.com/spreadsheets/d/1DsdxsrBJOk75sDGmXMsLLa15LHA7JaMlvKBZACG-RHY/edit?gid=1280887965#gid=1280887965"",""TESTE!D4"")"),950.0) -> 950 | I4: =IF(G4>0,(H4-G4)/G4,IF(H4>0,0,0)) -> 0
C5: =IFERROR(__xludf.DUMMYFUNCTION("IMPORTRANGE(""https://docs.google.com/spreadsheets/d/1DsdxsrBJOk75sDGmXMsLLa15LHA7JaMlvKBZACG-RHY/edit?gid=1280887965#gid=1280887965"",""TESTE!B5"")"),"AAT BTA-2 G2") -> AAT BTA-2 G2 | D5: =IFERROR(__xludf.DUMMYFUNCTION("IMPORTRANGE(""https://docs.google.com/spreadsheets/d/1DsdxsrBJOk75sDGmXMsLLa15LHA7JaMlvKBZACG-RHY/edit?gid=1280887965#gid=1280887965"",""TESTE!A5"")"),"AAT") -> AAT | E5: 0 | F5: 0 | G5: 0 | H5: =IFERROR(__xludf.DUMMYFUNCTION("IMPORTRANGE(""https://docs.google.com/spreadsheets/d/1DsdxsrBJOk75sDGmXMsLLa15LHA7JaMlvKBZACG-RHY/edit?gid=1280887965#gid=1280887965"",""TESTE!D5"")"),1350.0) -> 1350 | I5: =IF(G5>0,(H5-G5)/G5,IF(H5>0,0,0)) -> 0
C6: =IFERROR(__xludf.DUMMYFUNCTION("IMPORTRANGE(""https://docs.google.com/spreadsheets/d/1DsdxsrBJOk75sDGmXMsLLa15LHA7JaMlvKBZACG-RHY/edit?gid=1280887965#gid=1280887965"",""TESTE!B6"")"),"AAT BTA-3") -> AAT BTA-3 | D6: =IFERROR(__xludf.DUMMYFUNCTION("IMPORTRANGE(""https://docs.google.com/spreadsheets/d/1DsdxsrBJOk75sDGmXMsLLa15LHA7JaMlvKBZACG-RHY/edit?gid=1280887965#gid=1280887965"",""TESTE!A5"")"),"AAT") -> AAT | E6: 0 | F6: 0 | G6: 0 | H6: =IFERROR(__xludf.DUMMYFUNCTION("IMPORTRANGE(""https://docs.google.com/spreadsheets/d/1DsdxsrBJOk75sDGmXMsLLa15LHA7JaMlvKBZACG-RHY/edit?gid=1280887965#gid=1280887965"",""TESTE!D6"")"),1890.0) -> 1890 | I6: =IF(G6>0,(H6-G6)/G6,IF(H6>0,0,0)) -> 0
C7: =IFERROR(__xludf.DUMMYFUNCTION("IMPORTRANGE(""https://docs.google.com/spreadsheets/d/1DsdxsrBJOk75sDGmXMsLLa15LHA7JaMlvKBZACG-RHY/edit?gid=1280887965#gid=1280887965"",""TESTE!B7"")"),"AAT BTA-3 + AAT SLIM 6”") -> AAT BTA-3 + AAT SLIM 6” | D7: =IFERROR(__xludf.DUMMYFUNCTION("IMPORTRANGE(""https://docs.google.com/spreadsheets/d/1DsdxsrBJOk75sDGmXMsLLa15LHA7JaMlvKBZACG-RHY/edit?gid=1280887965#gid=1280887965"",""TESTE!A5"")"),"AAT") -> AAT | E7: 0 | F7: 0 | G7: 0 | H7: =IFERROR(__xludf.DUMMYFUNCTION("IMPORTRANGE(""https://docs.google.com/spreadsheets/d/1DsdxsrBJOk75sDGmXMsLLa15LHA7JaMlvKBZACG-RHY/edit?gid=1280887965#gid=1280887965"",""TESTE!D7"")"),2589.9) -> 2589.9 | I7: =IF(G7>0,(H7-G7)/G7,IF(H7>0,0,0)) -> 0
C8: =IFERROR(__xludf.DUMMYFUNCTION("IMPORTRANGE(""https://docs.google.com/spreadsheets/d/1DsdxsrBJOk75sDGmXMsLLa15LHA7JaMlvKBZACG-RHY/edit?gid=1280887965#gid=1280887965"",""TESTE!B8:B59"") "),"AAT BTS-1 Q") -> AAT BTS-1 Q | D8: =IFERROR(__xludf.DUMMYFUNCTION("IMPORTRANGE(""https://docs.google.com/spreadsheets/d/1DsdxsrBJOk75sDGmXMsLLa15LHA7JaMlvKBZACG-RHY/edit?gid=1280887965#gid=1280887965"",""TESTE!A5"")"),"AAT") -> AAT | E8: 0 | F8: 0 | G8: 0 | H8: =IFERROR(__xludf.DUMMYFUNCTION("IMPORTRANGE(""https://docs.google.com/spreadsheets/d/1DsdxsrBJOk75sDGmXMsLLa15LHA7JaMlvKBZACG-RHY/edit?gid=1280887965#gid=1280887965"",""TESTE!D8:d59"")"),2990.0) -> 2990 | I8: =IF(G8>0,(H8-G8)/G8,IF(H8>0,0,0)) -> 0
C9: =IFERROR(__xludf.DUMMYFUNCTION("""COMPUTED_VALUE"""),"AAT BTS-1 Q BLACK") -> AAT BTS-1 Q BLACK | D9: =IFERROR(__xludf.DUMMYFUNCTION("IMPORTRANGE(""https://docs.google.com/spreadsheets/d/1DsdxsrBJOk75sDGmXMsLLa15LHA7JaMlvKBZACG-RHY/edit?gid=1280887965#gid=1280887965"",""TESTE!A5"")"),"AAT") -> AAT | E9: 0 | F9: 0 | G9: 0 | H9: =IFERROR(__xludf.DUMMYFUNCTION("""COMPUTED_VALUE"""),2990.0) -> 2990 | I9: =IF(G9>0,(H9-G9)/G9,IF(H9>0,0,0)) -> 0
C10: =IFERROR(__xludf.DUMMYFUNCTION("""COMPUTED_VALUE"""),"AAT BTS-1 R") -> AAT BTS-1 R | D10: =IFERROR(__xludf.DUMMYFUNCTION("IMPORTRANGE(""https://docs.google.com/spreadsheets/d/1DsdxsrBJOk75sDGmXMsLLa15LHA7JaMlvKBZACG-RHY/edit?gid=1280887965#gid=1280887965"",""TESTE!A5"")"),"AAT") -> AAT | E10: 0 | F10: 0 | G10: 0 | H10: =IFERROR(__xludf.DUMMYFUNCTION("""COMPUTED_VALUE"""),2990.0) -> 2990 | I10: =IF(G10>0,(H10-G10)/G10,IF(H10>0,0,0)) -> 0
C11: =IFERROR(__xludf.DUMMYFUNCTION("""COMPUTED_VALUE"""),"AAT BTS-1 R BLACK") -> AAT BTS-1 R BLACK | D11: =IFERROR(__xludf.DUMMYFUNCTION("IMPORTRANGE(""https://docs.google.com/spreadsheets/d/1DsdxsrBJOk75sDGmXMsLLa15LHA7JaMlvKBZACG-RHY/edit?gid=1280887965#gid=1280887965"",""TESTE!A5"")"),"AAT") -> AAT | E11: 0 | F11: 0 | G11: 0 | H11: =IFERROR(__xludf.DUMMYFUNCTION("""COMPUTED_VALUE"""),2990.0) -> 2990 | I11: =IF(G11>0,(H11-G11)/G11,IF(H11>0,0,0)) -> 0
C12: =IFERROR(__xludf.DUMMYFUNCTION("""COMPUTED_VALUE"""),"AAT CUBE HOUT 12’’ BETON") -> AAT CUBE HOUT 12’’ BETON | D12: =IFERROR(__xludf.DUMMYFUNCTION("IMPORTRANGE(""https://docs.google.com/spreadsheets/d/1DsdxsrBJOk75sDGmXMsLLa15LHA7JaMlvKBZACG-RHY/edit?gid=1280887965#gid=1280887965"",""TESTE!A5"")"),"AAT") -> AAT | E12: 0 | F12: 0 | G12: 0 | H12: =IFERROR(__xludf.DUMMYFUNCTION("""COMPUTED_VALUE"""),5900.0) -> 5900 | I12: =IF(G12>0,(H12-G12)/G12,IF(H12>0,0,0)) -> 0
C13: =IFERROR(__xludf.DUMMYFUNCTION("""COMPUTED_VALUE"""),"AAT MA-1 G2") -> AAT MA-1 G2 | D13: =IFERROR(__xludf.DUMMYFUNCTION("IMPORTRANGE(""https://docs.google.com/spreadsheets/d/1DsdxsrBJOk75sDGmXMsLLa15LHA7JaMlvKBZACG-RHY/edit?gid=1280887965#gid=1280887965"",""TESTE!A5"")"),"AAT") -> AAT | E13: 0 | F13: 0 | G13: 0 | H13: =IFERROR(__xludf.DUMMYFUNCTION("""COMPUTED_VALUE"""),3200.0) -> 3200 | I13: =IF(G13>0,(H13-G13)/G13,IF(H13>0,0,0)) -> 0
C14: =IFERROR(__xludf.DUMMYFUNCTION("""COMPUTED_VALUE"""),"AAT MA-2 G2") -> AAT MA-2 G2 | D14: =IFERROR(__xludf.DUMMYFUNCTION("IMPORTRANGE(""https://docs.google.com/spreadsheets/d/1DsdxsrBJOk75sDGmXMsLLa15LHA7JaMlvKBZACG-RHY/edit?gid=1280887965#gid=1280887965"",""TESTE!A5"")"),"AAT") -> AAT | E14: 0 | F14: 0 | G14: 0 | H14: =IFERROR(__xludf.DUMMYFUNCTION("""COMPUTED_VALUE"""),3600.0) -> 3600 | I14: =IF(G14>0,(H14-G14)/G14,IF(H14>0,0,0)) -> 0
C15: =IFERROR(__xludf.DUMMYFUNCTION("""COMPUTED_VALUE"""),"AAT MA-3 G2") -> AAT MA-3 G2 | D15: =IFERROR(__xludf.DUMMYFUNCTION("IMPORTRANGE(""https://docs.google.com/spreadsheets/d/1DsdxsrBJOk75sDGmXMsLLa15LHA7JaMlvKBZACG-RHY/edit?gid=1280887965#gid=1280887965"",""TESTE!A5"")"),"AAT") -> AAT | E15: 0 | F15: 0 | G15: 0 | H15: =IFERROR(__xludf.DUMMYFUNCTION("""COMPUTED_VALUE"""),3900.0) -> 3900 | I15: =IF(G15>0,(H15-G15)/G15,IF(H15>0,0,0)) -> 0
C16: =IFERROR(__xludf.DUMMYFUNCTION("""COMPUTED_VALUE"""),"AAT MA-4 G2") -> AAT MA-4 G2 | D16: =IFERROR(__xludf.DUMMYFUNCTION("IMPORTRANGE(""https://docs.google.com/spreadsheets/d/1DsdxsrBJOk75sDGmXMsLLa15LHA7JaMlvKBZACG-RHY/edit?gid=1280887965#gid=1280887965"",""TESTE!A5"")"),"AAT") -> AAT | E16: 0 | F16: 0 | G16: 0 | H16: =IFERROR(__xludf.DUMMYFUNCTION("""COMPUTED_VALUE"""),4550.0) -> 4550 | I16: =IF(G16>0,(H16-G16)/G16,IF(H16>0,0,0)) -> 0
C17: =IFERROR(__xludf.DUMMYFUNCTION("""COMPUTED_VALUE"""),"AAT MP-1") -> AAT MP-1 | D17: =IFERROR(__xludf.DUMMYFUNCTION("IMPORTRANGE(""https://docs.google.com/spreadsheets/d/1DsdxsrBJOk75sDGmXMsLLa15LHA7JaMlvKBZACG-RHY/edit?gid=1280887965#gid=1280887965"",""TESTE!A5"")"),"AAT") -> AAT | E17: 0 | F17: 0 | G17: 0 | H17: =IFERROR(__xludf.DUMMYFUNCTION("""COMPUTED_VALUE"""),1990.0) -> 1990 | I17: =IF(G17>0,(H17-G17)/G17,IF(H17>0,0,0)) -> 0
C18: =IFERROR(__xludf.DUMMYFUNCTION("""COMPUTED_VALUE"""),"AAT PA-200") -> AAT PA-200 | D18: =IFERROR(__xludf.DUMMYFUNCTION("IMPORTRANGE(""https://docs.google.com/spreadsheets/d/1DsdxsrBJOk75sDGmXMsLLa15LHA7JaMlvKBZACG-RHY/edit?gid=1280887965#gid=1280887965"",""TESTE!A5"")"),"AAT") -> AAT | E18: 0 | F18: 0 | G18: 0 | H18: =IFERROR(__xludf.DUMMYFUNCTION("""COMPUTED_VALUE"""),1750.0) -> 1750 | I18: =IF(G18>0,(H18-G18)/G18,IF(H18>0,0,0)) -> 0
C19: =IFERROR(__xludf.DUMMYFUNCTION("""COMPUTED_VALUE"""),"AAT PA-60") -> AAT PA-60 | D19: =IFERROR(__xludf.DUMMYFUNCTION("IMPORTRANGE(""https://docs.google.com/spreadsheets/d/1DsdxsrBJOk75sDGmXMsLLa15LHA7JaMlvKBZACG-RHY/edit?gid=1280887965#gid=1280887965"",""TESTE!A5"")"),"AAT") -> AAT | E19: 0 | F19: 0 | G19: 0 | H19: =IFERROR(__xludf.DUMMYFUNCTION("""COMPUTED_VALUE"""),850.0) -> 850 | I19: =IF(G19>0,(H19-G19)/G19,IF(H19>0,0,0)) -> 0
C20: =IFERROR(__xludf.DUMMYFUNCTION("""COMPUTED_VALUE"""),"AAT PM-1 G2") -> AAT PM-1 G2 | D20: =IFERROR(__xludf.DUMMYFUNCTION("IMPORTRANGE(""https://docs.google.com/spreadsheets/d/1DsdxsrBJOk75sDGmXMsLLa15LHA7JaMlvKBZACG-RHY/edit?gid=1280887965#gid=1280887965"",""TESTE!A5"")"),"AAT") -> AAT | E20: 0 | F20: 0 | G20: 0 | H20: =IFERROR(__xludf.DUMMYFUNCTION("""COMPUTED_VALUE"""),3550.0) -> 3550 | I20: =IF(G20>0,(H20-G20)/G20,IF(H20>0,0,0)) -> 0
C21: =IFERROR(__xludf.DUMMYFUNCTION("""COMPUTED_VALUE"""),"AAT PM-10 CI") -> AAT PM-10 CI | D21: =IFERROR(__xludf.DUMMYFUNCTION("IMPORTRANGE(""https://docs.google.com/spreadsheets/d/1DsdxsrBJOk75sDGmXMsLLa15LHA7JaMlvKBZACG-RHY/edit?gid=1280887965#gid=1280887965"",""TESTE!A5"")"),"AAT") -> AAT | E21: 0 | F21: 0 | G21: 0 | H21: =IFERROR(__xludf.DUMMYFUNCTION("""COMPUTED_VALUE"""),3250.0) -> 3250 | I21: =IF(G21>0,(H21-G21)/G21,IF(H21>0,0,0)) -> 0
C22: =IFERROR(__xludf.DUMMYFUNCTION("""COMPUTED_VALUE"""),"AAT PM-11 CI") -> AAT PM-11 CI | D22: =IFERROR(__xludf.DUMMYFUNCTION("IMPORTRANGE(""https://docs.google.com/spreadsheets/d/1DsdxsrBJOk75sDGmXMsLLa15LHA7JaMlvKBZACG-RHY/edit?gid=1280887965#gid=1280887965"",""TESTE!A5"")"),"AAT") -> AAT | E22: 0 | F22: 0 | G22: 0 | H22: =IFERROR(__xludf.DUMMYFUNCTION("""COMPUTED_VALUE"""),4050.0) -> 4050 | I22: =IF(G22>0,(H22-G22)/G22,IF(H22>0,0,0)) -> 0
C23: =IFERROR(__xludf.DUMMYFUNCTION("""COMPUTED_VALUE"""),"AAT PM-2") -> AAT PM-2 | D23: =IFERROR(__xludf.DUMMYFUNCTION("IMPORTRANGE(""https://docs.google.com/spreadsheets/d/1DsdxsrBJOk75sDGmXMsLLa15LHA7JaMlvKBZACG-RHY/edit?gid=1280887965#gid=1280887965"",""TESTE!A5"")"),"AAT") -> AAT | E23: 0 | F23: 0 | G23: 0 | H23: =IFERROR(__xludf.DUMMYFUNCTION("""COMPUTED_VALUE"""),9800.0) -> 9800 | I23: =IF(G23>0,(H23-G23)/G23,IF(H23>0,0,0)) -> 0
C24: =IFERROR(__xludf.DUMMYFUNCTION("""COMPUTED_VALUE"""),"AAT PM-4 G2") -> AAT PM-4 G2 | D24: =IFERROR(__xludf.DUMMYFUNCTION("IMPORTRANGE(""https://docs.google.com/spreadsheets/d/1DsdxsrBJOk75sDGmXMsLLa15LHA7JaMlvKBZACG-RHY/edit?gid=1280887965#gid=1280887965"",""TESTE!A5"")"),"AAT") -> AAT | E24: 0 | F24: 0 | G24: 0 | H24: =IFERROR(__xludf.DUMMYFUNCTION("""COMPUTED_VALUE"""),5700.0) -> 5700 | I24: =IF(G24>0,(H24-G24)/G24,IF(H24>0,0,0)) -> 0
C25: =IFERROR(__xludf.DUMMYFUNCTION("""COMPUTED_VALUE"""),"AAT PM-5") -> AAT PM-5 | D25: =IFERROR(__xludf.DUMMYFUNCTION("IMPORTRANGE(""https://docs.google.com/spreadsheets/d/1DsdxsrBJOk75sDGmXMsLLa15LHA7JaMlvKBZACG-RHY/edit?gid=1280887965#gid=1280887965"",""TESTE!A5"")"),"AAT") -> AAT | E25: 0 | F25: 0 | G25: 0 | H25: =IFERROR(__xludf.DUMMYFUNCTION("""COMPUTED_VALUE"""),8750.0) -> 8750 | I25: =IF(G25>0,(H25-G25)/G25,IF(H25>0,0,0)) -> 0
C26: =IFERROR(__xludf.DUMMYFUNCTION("""COMPUTED_VALUE"""),"AAT PM-6 CI") -> AAT PM-6 CI | D26: =IFERROR(__xludf.DUMMYFUNCTION("IMPORTRANGE(""https://docs.google.com/spreadsheets/d/1DsdxsrBJOk75sDGmXMsLLa15LHA7JaMlvKBZACG-RHY/edit?gid=1280887965#gid=1280887965"",""TESTE!A5"")"),"AAT") -> AAT | E26: 0 | F26: 0 | G26: 0 | H26: =IFERROR(__xludf.DUMMYFUNCTION("""COMPUTED_VALUE"""),4200.0) -> 4200 | I26: =IF(G26>0,(H26-G26)/G26,IF(H26>0,0,0)) -> 0
C27: =IFERROR(__xludf.DUMMYFUNCTION("""COMPUTED_VALUE"""),"AAT PM-7 CI") -> AAT PM-7 CI | D27: =IFERROR(__xludf.DUMMYFUNCTION("IMPORTRANGE(""https://docs.google.com/spreadsheets/d/1DsdxsrBJOk75sDGmXMsLLa15LHA7JaMlvKBZACG-RHY/edit?gid=1280887965#gid=1280887965"",""TESTE!A5"")"),"AAT") -> AAT | E27: 0 | F27: 0 | G27: 0 | H27: =IFERROR(__xludf.DUMMYFUNCTION("""COMPUTED_VALUE"""),4930.0) -> 4930 | I27: =IF(G27>0,(H27-G27)/G27,IF(H27>0,0,0)) -> 0
C28: =IFERROR(__xludf.DUMMYFUNCTION("""COMPUTED_VALUE"""),"AAT PM-8 CI") -> AAT PM-8 CI | D28: =IFERROR(__xludf.DUMMYFUNCTION("IMPORTRANGE(""https://docs.google.com/spreadsheets/d/1DsdxsrBJOk75sDGmXMsLLa15LHA7JaMlvKBZACG-RHY/edit?gid=1280887965#gid=1280887965"",""TESTE!A5"")"),"AAT") -> AAT | E28: 0 | F28: 0 | G28: 0 | H28: =IFERROR(__xludf.DUMMYFUNCTION("""COMPUTED_VALUE"""),4800.0) -> 4800 | I28: =IF(G28>0,(H28-G28)/G28,IF(H28>0,0,0)) -> 0
C29: =IFERROR(__xludf.DUMMYFUNCTION("""COMPUTED_VALUE"""),"AAT PM-9 CI") -> AAT PM-9 CI | D29: =IFERROR(__xludf.DUMMYFUNCTION("IMPORTRANGE(""https://docs.google.com/spreadsheets/d/1DsdxsrBJOk75sDGmXMsLLa15LHA7JaMlvKBZACG-RHY/edit?gid=1280887965#gid=1280887965"",""TESTE!A5"")"),"AAT") -> AAT | E29: 0 | F29: 0 | G29: 0 | H29: =IFERROR(__xludf.DUMMYFUNCTION("""COMPUTED_VALUE"""),6600.0) -> 6600 | I29: =IF(G29>0,(H29-G29)/G29,IF(H29>0,0,0)) -> 0
C30: =IFERROR(__xludf.DUMMYFUNCTION("""COMPUTED_VALUE"""),"AAT PMR-1") -> AAT PMR-1 | D30: =IFERROR(__xludf.DUMMYFUNCTION("IMPORTRANGE(""https://docs.google.com/spreadsheets/d/1DsdxsrBJOk75sDGmXMsLLa15LHA7JaMlvKBZACG-RHY/edit?gid=1280887965#gid=1280887965"",""TESTE!A5"")"),"AAT") -> AAT | E30: 0 | F30: 0 | G30: 0 | H30: =IFERROR(__xludf.DUMMYFUNCTION("""COMPUTED_VALUE"""),3880.0) -> 3880 | I30: =IF(G30>0,(H30-G30)/G30,IF(H30>0,0,0)) -> 0
C31: =IFERROR(__xludf.DUMMYFUNCTION("""COMPUTED_VALUE"""),"AAT PMR-10") -> AAT PMR-10 | D31: =IFERROR(__xludf.DUMMYFUNCTION("IMPORTRANGE(""https://docs.google.com/spreadsheets/d/1DsdxsrBJOk75sDGmXMsLLa15LHA7JaMlvKBZACG-RHY/edit?gid=1280887965#gid=1280887965"",""TESTE!A5"")"),"AAT") -> AAT | E31: 0 | F31: 0 | G31: 0 | H31: =IFERROR(__xludf.DUMMYFUNCTION("""COMPUTED_VALUE"""),15000.0) -> 15000 | I31: =IF(G31>0,(H31-G31)/G31,IF(H31>0,0,0)) -> 0
C32: =IFERROR(__xludf.DUMMYFUNCTION("""COMPUTED_VALUE"""),"AAT PMR-10 G2") -> AAT PMR-10 G2 | D32: =IFERROR(__xludf.DUMMYFUNCTION("IMPORTRANGE(""https://docs.google.com/spreadsheets/d/1DsdxsrBJOk75sDGmXMsLLa15LHA7JaMlvKBZACG-RHY/edit?gid=1280887965#gid=1280887965"",""TESTE!A5"")"),"AAT") -> AAT | E32: 0 | F32: 0 | G32: 0 | H32: =IFERROR(__xludf.DUMMYFUNCTION("""COMPUTED_VALUE"""),15000.0) -> 15000 | I32: =IF(G32>0,(H32-G32)/G32,IF(H32>0,0,0)) -> 0
C33: =IFERROR(__xludf.DUMMYFUNCTION("""COMPUTED_VALUE"""),"AAT PMR-11 G2") -> AAT PMR-11 G2 | D33: =IFERROR(__xludf.DUMMYFUNCTION("IMPORTRANGE(""https://docs.google.com/spreadsheets/d/1DsdxsrBJOk75sDGmXMsLLa15LHA7JaMlvKBZACG-RHY/edit?gid=1280887965#gid=1280887965"",""TESTE!A5"")"),"AAT") -> AAT | E33: 0 | F33: 0 | G33: 0 | H33: =IFERROR(__xludf.DUMMYFUNCTION("""COMPUTED_VALUE"""),13800.0) -> 13800 | I33: =IF(G33>0,(H33-G33)/G33,IF(H33>0,0,0)) -> 0
C34: =IFERROR(__xludf.DUMMYFUNCTION("""COMPUTED_VALUE"""),"AAT PMR-12") -> AAT PMR-12 | D34: =IFERROR(__xludf.DUMMYFUNCTION("IMPORTRANGE(""https://docs.google.com/spreadsheets/d/1DsdxsrBJOk75sDGmXMsLLa15LHA7JaMlvKBZACG-RHY/edit?gid=1280887965#gid=1280887965"",""TESTE!A5"")"),"AAT") -> AAT | E34: 0 | F34: 0 | G34: 0 | H34: =IFERROR(__xludf.DUMMYFUNCTION("""COMPUTED_VALUE"""),16000.0) -> 16000 | I34: =IF(G34>0,(H34-G34)/G34,IF(H34>0,0,0)) -> 0
C35: =IFERROR(__xludf.DUMMYFUNCTION("""COMPUTED_VALUE"""),"AAT PMR-12 G2") -> AAT PMR-12 G2 | D35: =IFERROR(__xludf.DUMMYFUNCTION("IMPORTRANGE(""https://docs.google.com/spreadsheets/d/1DsdxsrBJOk75sDGmXMsLLa15LHA7JaMlvKBZACG-RHY/edit?gid=1280887965#gid=1280887965"",""TESTE!A5"")"),"AAT") -> AAT | E35: 0 | F35: 0 | G35: 0 | H35: =IFERROR(__xludf.DUMMYFUNCTION("""COMPUTED_VALUE"""),16000.0) -> 16000 | I35: =IF(G35>0,(H35-G35)/G35,IF(H35>0,0,0)) -> 0
C36: =IFERROR(__xludf.DUMMYFUNCTION("""COMPUTED_VALUE"""),"AAT PMR-2") -> AAT PMR-2 | D36: =IFERROR(__xludf.DUMMYFUNCTION("IMPORTRANGE(""https://docs.google.com/spreadsheets/d/1DsdxsrBJOk75sDGmXMsLLa15LHA7JaMlvKBZACG-RHY/edit?gid=1280887965#gid=1280887965"",""TESTE!A5"")"),"AAT") -> AAT | E36: 0 | F36: 0 | G36: 0 | H36: =IFERROR(__xludf.DUMMYFUNCTION("""COMPUTED_VALUE"""),3050.0) -> 3050 | I36: =IF(G36>0,(H36-G36)/G36,IF(H36>0,0,0)) -> 0
C37: =IFERROR(__xludf.DUMMYFUNCTION("""COMPUTED_VALUE"""),"AAT PMR-3") -> AAT PMR-3 | D37: =IFERROR(__xludf.DUMMYFUNCTION("IMPORTRANGE(""https://docs.google.com/spreadsheets/d/1DsdxsrBJOk75sDGmXMsLLa15LHA7JaMlvKBZACG-RHY/edit?gid=1280887965#gid=1280887965"",""TESTE!A5"")"),"AAT") -> AAT | E37: 0 | F37: 0 | G37: 0 | H37: =IFERROR(__xludf.DUMMYFUNCTION("""COMPUTED_VALUE"""),2100.0) -> 2100 | I37: =IF(G37>0,(H37-G37)/G37,IF(H37>0,0,0)) -> 0
C38: =IFERROR(__xludf.DUMMYFUNCTION("""COMPUTED_VALUE"""),"AAT PMR-4 G2") -> AAT PMR-4 G2 | D38: =IFERROR(__xludf.DUMMYFUNCTION("IMPORTRANGE(""https://docs.google.com/spreadsheets/d/1DsdxsrBJOk75sDGmXMsLLa15LHA7JaMlvKBZACG-RHY/edit?gid=1280887965#gid=1280887965"",""TESTE!A5"")"),"AAT") -> AAT | E38: 0 | F38: 0 | G38: 0 | H38: =IFERROR(__xludf.DUMMYFUNCTION("""COMPUTED_VALUE"""),9500.0) -> 9500 | I38: =IF(G38>0,(H38-G38)/G38,IF(H38>0,0,0)) -> 0
C39: =IFERROR(__xludf.DUMMYFUNCTION("""COMPUTED_VALUE"""),"AAT PMR-5") -> AAT PMR-5 | D39: =IFERROR(__xludf.DUMMYFUNCTION("IMPORTRANGE(""https://docs.google.com/spreadsheets/d/1DsdxsrBJOk75sDGmXMsLLa15LHA7JaMlvKBZACG-RHY/edit?gid=1280887965#gid=1280887965"",""TESTE!A5"")"),"AAT") -> AAT | E39: 0 | F39: 0 | G39: 0 | H39: =IFERROR(__xludf.DUMMYFUNCTION("""COMPUTED_VALUE"""),12100.0) -> 12100 | I39: =IF(G39>0,(H39-G39)/G39,IF(H39>0,0,0)) -> 0
C40: =IFERROR(__xludf.DUMMYFUNCTION("""COMPUTED_VALUE"""),"AAT PMR-5 G2") -> AAT PMR-5 G2 | D40: =IFERROR(__xludf.DUMMYFUNCTION("IMPORTRANGE(""https://docs.google.com/spreadsheets/d/1DsdxsrBJOk75sDGmXMsLLa15LHA7JaMlvKBZACG-RHY/edit?gid=1280887965#gid=1280887965"",""TESTE!A5"")"),"AAT") -> AAT | E40: 0 | F40: 0 | G40: 0 | H40: =IFERROR(__xludf.DUMMYFUNCTION("""COMPUTED_VALUE"""),12100.0) -> 12100 | I40: =IF(G40>0,(H40-G40)/G40,IF(H40>0,0,0)) -> 0
...

Sheet ESTOQUE
D1: CATEGORIA | E1: PRODUTO | F1: SALDO | G1: ENTRADA | H1: SAIDA | I1: CUSTO | J1: CUSTO TOTAL
D2: ACESSÓRIO | E2: ANTENNA PROTECT | F2: =G2-H2 -> 1 | G2: =SUMIFS('LANÇAMENTOS'!$H:$H,'LANÇAMENTOS'!$E:$E,"ENTRADA",'LANÇAMENTOS'!$G:$G,$E2) -> 1 | H2: =SUMIFS('LANÇAMENTOS'!$H:$H,'LANÇAMENTOS'!$E:$E,"SAIDA",'LANÇAMENTOS'!$G:$G,$E2) -> 0 | J2: =I2*F2 -> 0
A3: ATUALIZADO EM 10/04/2025 | D3: ACESSÓRIO | E3: CABLE PROTECT | F3: =G3-H3 -> 1 | G3: =SUMIFS('LANÇAMENTOS'!$H:$H,'LANÇAMENTOS'!$E:$E,"ENTRADA",'LANÇAMENTOS'!$G:$G,$E3) -> 1 | H3: =SUMIFS('LANÇAMENTOS'!$H:$H,'LANÇAMENTOS'!$E:$E,"SAIDA",'LANÇAMENTOS'!$G:$G,$E3) -> 0 | J3: =I3*F3 -> 0
D4: ACESSÓRIO | E4: KIT PASSADOR DE FIO EXPANSÍVEL | F4: =G4-H4 -> 7 | G4: =SUMIFS('LANÇAMENTOS'!$H:$H,'LANÇAMENTOS'!$E:$E,"ENTRADA",'LANÇAMENTOS'!$G:$G,$E4) -> 7 | H4: =SUMIFS('LANÇAMENTOS'!$H:$H,'LANÇAMENTOS'!$E:$E,"SAIDA",'LANÇAMENTOS'!$G:$G,$E4) -> 0 | J4: =I4*F4 -> 0
D5: ACESSÓRIO | E5: MICROFONE PARA CALIBRAÇÃO | F5: =G5-H5 -> 5 | G5: =SUMIFS('LANÇAMENTOS'!$H:$H,'LANÇAMENTOS'!$E:$E,"ENTRADA",'LANÇAMENTOS'!$G:$G,$E5) -> 6 | H5: =SUMIFS('LANÇAMENTOS'!$H:$H,'LANÇAMENTOS'!$E:$E,"SAIDA",'LANÇAMENTOS'!$G:$G,$E5) -> 1 | J5: =I5*F5 -> 0
D6: ACESSÓRIO | E6: ABRAÇADEIRAS | F6: =G6-H6 -> 11 | G6: =SUMIFS('LANÇAMENTOS'!$H:$H,'LANÇAMENTOS'!$E:$E,"ENTRADA",'LANÇAMENTOS'!$G:$G,$E6) -> 11 | H6: =SUMIFS('LANÇAMENTOS'!$H:$H,'LANÇAMENTOS'!$E:$E,"SAIDA",'LANÇAMENTOS'!$G:$G,$E6) -> 0 | J6: =I6*F6 -> 0
D7: ACESSÓRIO | E7: EMENDA HDMI RETO | F7: =G7-H7 -> 11 | G7: =SUMIFS('LANÇAMENTOS'!$H:$H,'LANÇAMENTOS'!$E:$E,"ENTRADA",'LANÇAMENTOS'!$G:$G,$E7) -> 11 | H7: =SUMIFS('LANÇAMENTOS'!$H:$H,'LANÇAMENTOS'!$E:$E,"SAIDA",'LANÇAMENTOS'!$G:$G,$E7) -> 0 | J7: =I7*F7 -> 0
D8: ACESSÓRIO | E8: EMENDA HDMI EM L | F8: =G8-H8 -> 4 | G8: =SUMIFS('LANÇAMENTOS'!$H:$H,'LANÇAMENTOS'!$E:$E,"ENTRADA",'LANÇAMENTOS'!$G:$G,$E8) -> 4 | H8: =SUMIFS('LANÇAMENTOS'!$H:$H,'LANÇAMENTOS'!$E:$E,"SAIDA",'LANÇAMENTOS'!$G:$G,$E8) -> 0 | J8: =I8*F8 -> 0
D9: ACESSÓRIO | E9: RÉGUA 5 TOMADAS COM LIGA | F9: =G9-H9 -> 1 | G9: =SUMIFS('LANÇAMENTOS'!$H:$H,'LANÇAMENTOS'!$E:$E,"ENTRADA",'LANÇAMENTOS'!$G:$G,$E9) -> 3 | H9: =SUMIFS('LANÇAMENTOS'!$H:$H,'LANÇAMENTOS'!$E:$E,"SAIDA",'LANÇAMENTOS'!$G:$G,$E9) -> 2 | J9: =I9*F9 -> 0
D10: AMPLIFICADOR | E10: HAYONIK APLIFICADOR 450 | F10: =G10-H10 -> 3 | G10: =SUMIFS('LANÇAMENTOS'!$H:$H,'LANÇAMENTOS'!$E:$E,"ENTRADA",'LANÇAMENTOS'!$G:$G,$E10) -> 3 | H10: =SUMIFS('LANÇAMENTOS'!$H:$H,'LANÇAMENTOS'!$E:$E,"SAIDA",'LANÇAMENTOS'!$G:$G,$E10) -> 0 | J10: =I10*F10 -> 0
D11: APARELHO | E11: HDMI ARC | F11: =G11-H11 -> 8 | G11: =SUMIFS('LANÇAMENTOS'!$H:$H,'LANÇAMENTOS'!$E:$E,"ENTRADA",'LANÇAMENTOS'!$G:$G,$E11) -> 8 | H11: =SUMIFS('LANÇAMENTOS'!$H:$H,'LANÇAMENTOS'!$E:$E,"SAIDA",'LANÇAMENTOS'!$G:$G,$E11) -> 0 | J11: =I11*F11 -> 0
D12: APARELHO | E12: SWITCH HIKVISION 8P 1GB | F12: =G12-H12 -> 3 | G12: =SUMIFS('LANÇAMENTOS'!$H:$H,'LANÇAMENTOS'!$E:$E,"ENTRADA",'LANÇAMENTOS'!$G:$G,$E12) -> 3 | H12: =SUMIFS('LANÇAMENTOS'!$H:$H,'LANÇAMENTOS'!$E:$E,"SAIDA",'LANÇAMENTOS'!$G:$G,$E12) -> 0 | J12: =I12*F12 -> 0
D13: APARELHO | E13: SWITCH HIKVISION 5P 1GB | F13: =G13-H13 -> 2 | G13: =SUMIFS('LANÇAMENTOS'!$H:$H,'LANÇAMENTOS'!$E:$E,"ENTRADA",'LANÇAMENTOS'!$G:$G,$E13) -> 2 | H13: =SUMIFS('LANÇAMENTOS'!$H:$H,'LANÇAMENTOS'!$E:$E,"SAIDA",'LANÇAMENTOS'!$G:$G,$E13) -> 0 | J13: =I13*F13 -> 0
D14: APARELHO | E14: SWITCH MERCURYS 8P FAST | F14: =G14-H14 -> 2 | G14: =SUMIFS('LANÇAMENTOS'!$H:$H,'LANÇAMENTOS'!$E:$E,"ENTRADA",'LANÇAMENTOS'!$G:$G,$E14) -> 2 | H14: =SUMIFS('LANÇAMENTOS'!$H:$H,'LANÇAMENTOS'!$E:$E,"SAIDA",'LANÇAMENTOS'!$G:$G,$E14) -> 0 | J14: =I14*F14 -> 0
D15: APARELHO | E15: SWITCH MERCURYS 5P FAST | F15: =G15-H15 -> 1 | G15: =SUMIFS('LANÇAMENTOS'!$H:$H,'LANÇAMENTOS'!$E:$E,"ENTRADA",'LANÇAMENTOS'!$G:$G,$E15) -> 1 | H15: =SUMIFS('LANÇAMENTOS'!$H:$H,'LANÇAMENTOS'!$E:$E,"SAIDA",'LANÇAMENTOS'!$G:$G,$E15) -> 0 | J15: =I15*F15 -> 0
... D28: CABO | E28: HDMI STORM 0,5m | F28: =G28-H28 -> 0 | G28: =SUMIFS('LANÇAMENTOS'!$H:$H,'LANÇAMENTOS'!$E:$E,"ENTRADA",'LANÇAMENTOS'!$G:$G,$E28) -> 0 | H28: =SUMIFS('LANÇAMENTOS'!$H:$H,'LANÇAMENTOS'!$E:$E,"SAIDA",'LANÇAMENTOS'!$G:$G,$E28) -> 0 | J28: =I28*F28 -> 0
D29: CABO | E29: HDMI STORM 1,5m | F29: =G29-H29 -> 20 | G29: =SUMIFS('LANÇAMENTOS'!$H:$H,'LANÇAMENTOS'!$E:$E,"ENTRADA",'LANÇAMENTOS'!$G:$G,$E29) -> 23 | H29: =SUMIFS('LANÇAMENTOS'!$H:$H,'LANÇAMENTOS'!$E:$E,"SAIDA",'LANÇAMENTOS'!$G:$G,$E29) -> 3 | I29: 27.61 | J29: =I29*F29 -> 552.2
D30: CABO | E30: HDMI STORM 1m | F30: =G30-H30 -> 13 | G30: =SUMIFS('LANÇAMENTOS'!$H:$H,'LANÇAMENTOS'!$E:$E,"ENTRADA",'LANÇAMENTOS'!$G:$G,$E30) -> 13 | H30: =SUMIFS('LANÇAMENTOS'!$H:$H,'LANÇAMENTOS'!$E:$E,"SAIDA",'LANÇAMENTOS'!$G:$G,$E30) -> 0 | I30: 14.63 | J30: =I30*F30 -> 190.19
D31: CABO | E31: HDMI STORM 2m | F31: =G31-H31 -> 17 | G31: =SUMIFS('LANÇAMENTOS'!$H:$H,'LANÇAMENTOS'!$E:$E,"ENTRADA",'LANÇAMENTOS'!$G:$G,$E31) -> 20 | H31: =SUMIFS('LANÇAMENTOS'!$H:$H,'LANÇAMENTOS'!$E:$E,"SAIDA",'LANÇAMENTOS'!$G:$G,$E31) -> 3 | I31: 30.83 | J31: =I31*F31 -> 524.11
D32: CABO | E32: HDMI STORM 3m | F32: =G32-H32 -> 12 | G32: =SUMIFS('LANÇAMENTOS'!$H:$H,'LANÇAMENTOS'!$E:$E,"ENTRADA",'LANÇAMENTOS'!$G:$G,$E32) -> 15 | H32: =SUMIFS('LANÇAMENTOS'!$H:$H,'LANÇAMENTOS'!$E:$E,"SAIDA",'LANÇAMENTOS'!$G:$G,$E32) -> 3 | I32: 25.03 | J32: =I32*F32 -> 300.36
D33: CABO | E33: HDMI STORM 5m | F33: =G33-H33 -> 0 | G33: =SUMIFS('LANÇAMENTOS'!$H:$H,'LANÇAMENTOS'!$E:$E,"ENTRADA",'LANÇAMENTOS'!$G:$G,$E33) -> 0 | H33: =SUMIFS('LANÇAMENTOS'!$H:$H,'LANÇAMENTOS'!$E:$E,"SAIDA",'LANÇAMENTOS'!$G:$G,$E33) -> 0 | I33: 49.61 | J33: =I33*F33 -> 0
D34: CABO | E34: RCA Y 1 MACHO + 2 FÊMES 90 GRAUS | F34: =G34-H34 -> 13 | G34: =SUMIFS('LANÇAMENTOS'!$H:$H,'LANÇAMENTOS'!$E:$E,"ENTRADA",'LANÇAMENTOS'!$G:$G,$E34) -> 13 | H34: =SUMIFS('LANÇAMENTOS'!$H:$H,'LANÇAMENTOS'!$E:$E,"SAIDA",'LANÇAMENTOS'!$G:$G,$E34) -> 0 | J34: =I34*F34 -> 0
D35: CABO | E35: TOSLINK PIX 10m | F35: =G35-H35 -> 6 | G35: =SUMIFS('LANÇAMENTOS'!$H:$H,'LANÇAMENTOS'!$E:$E,"ENTRADA",'LANÇAMENTOS'!$G:$G,$E35) -> 6 | H35: =SUMIFS('LANÇAMENTOS'!$H:$H,'LANÇAMENTOS'!$E:$E,"SAIDA",'LANÇAMENTOS'!$G:$G,$E35) -> 0 | J35: =I35*F35 -> 0
D36: CABO | E36: TOSLINK PIX 1m | F36: =G36-H36 -> 4 | G36: =SUMIFS('LANÇAMENTOS'!$H:$H,'LANÇAMENTOS'!$E:$E,"ENTRADA",'LANÇAMENTOS'!$G:$G,$E36) -> 7 | H36: =SUMIFS('LANÇAMENTOS'!$H:$H,'LANÇAMENTOS'!$E:$E,"SAIDA",'LANÇAMENTOS'!$G:$G,$E36) -> 3 | J36: =I36*F36 -> 0
D37: CABO | E37: TOSLINK PIX 2m | F37: =G37-H37 -> 20 | G37: =SUMIFS('LANÇAMENTOS'!$H:$H,'LANÇAMENTOS'!$E:$E,"ENTRADA",'LANÇAMENTOS'!$G:$G,$E37) -> 21 | H37: =SUMIFS('LANÇAMENTOS'!$H:$H,'LANÇAMENTOS'!$E:$E,"SAIDA",'LANÇAMENTOS'!$G:$G,$E37) -> 1 | J37: =I37*F37 -> 0
D38: CABO | E38: TOSLINK PIX 3m | F38: =G38-H38 -> 5 | G38: =SUMIFS('LANÇAMENTOS'!$H:$H,'LANÇAMENTOS'!$E:$E,"ENTRADA",'LANÇAMENTOS'!$G:$G,$E38) -> 6 | H38: =SUMIFS('LANÇAMENTOS'!$H:$H,'LANÇAMENTOS'!$E:$E,"SAIDA",'LANÇAMENTOS'!$G:$G,$E38) -> 1 | J38: =I38*F38 -> 0
D39: CABO | E39: TOSLINK PIX 5m | F39: =G39-H39 -> 6 | G39: =SUMIFS('LANÇAMENTOS'!$H:$H,'LANÇAMENTOS'!$E:$E,"ENTRADA",'LANÇAMENTOS'!$G:$G,$E39) -> 8 | H39: =SUMIFS('LANÇAMENTOS'!$H:$H,'LANÇAMENTOS'!$E:$E,"SAIDA",'LANÇAMENTOS'!$G:$G,$E39) -> 2 | J39: =I39*F39 -> 0
D40: CABO | E40: CABO 4P X 24 300M | F40: =G40-H40 -> 0.25 | G40: =SUMIFS('LANÇAMENTOS'!$H:$H,'LANÇAMENTOS'!$E:$E,"ENTRADA",'LANÇAMENTOS'!$G:$G,$E40) -> 0.25 | H40: =SUMIFS('LANÇAMENTOS'!$H:$H,'LANÇAMENTOS'!$E:$E,"SAIDA",'LANÇAMENTOS'!$G:$G,$E40) -> 0 | J40: =I40*F40 -> 0
D41: CABO | E41: RCA STORM 5M | F41: =G41-H41 -> 6 | G41: =SUMIFS('LANÇAMENTOS'!$H:$H,'LANÇAMENTOS'!$E:$E,"ENTRADA",'LANÇAMENTOS'!$G:$G,$E41) -> 6 | H41: =SUMIFS('LANÇAMENTOS'!$H:$H,'LANÇAMENTOS'!$E:$E,"SAIDA",'LANÇAMENTOS'!$G:$G,$E41) -> 0 | J41: =I41*F41 -> 0
D42: CABO | E42: RCA STORM 3M | F42: =G42-H42 -> 6 | G42: =SUMIFS('LANÇAMENTOS'!$H:$H,'LANÇAMENTOS'!$E:$E,"ENTRADA",'LANÇAMENTOS'!$G:$G,$E42) -> 6 | H42: =SUMIFS('LANÇAMENTOS'!$H:$H,'LANÇAMENTOS'!$E:$E,"SAIDA",'LANÇAMENTOS'!$G:$G,$E42) -> 0 | J42: =I42*F42 -> 0
D43: CABO | E43: RCA STORM 1M | F43: =G43-H43 -> 16 | G43: =SUMIFS('LANÇAMENTOS'!$H:$H,'LANÇAMENTOS'!$E:$E,"ENTRADA",'LANÇAMENTOS'!$G:$G,$E43) -> 16 | H43: =SUMIFS('LANÇAMENTOS'!$H:$H,'LANÇAMENTOS'!$E:$E,"SAIDA",'LANÇAMENTOS'!$G:$G,$E43) -> 0 | J43: =I43*F43 -> 0
D44: CABO | E44: TOSLINK DMD 1,5M | F44: =G44-H44 -> 4 | G44: =SUMIFS('LANÇAMENTOS'!$H:$H,'LANÇAMENTOS'!$E:$E,"ENTRADA",'LANÇAMENTOS'!$G:$G,$E44) -> 4 | H44: =SUMIFS('LANÇAMENTOS'!$H:$H,'LANÇAMENTOS'!$E:$E,"SAIDA",'LANÇAMENTOS'!$G:$G,$E44) -> 0 | J44: =I44*F44 -> 0
D45: CABO | E45: TOSLINK DMD 3M | F45: =G45-H45 -> 3 | G45: =SUMIFS('LANÇAMENTOS'!$H:$H,'LANÇAMENTOS'!$E:$E,"ENTRADA",'LANÇAMENTOS'!$G:$G,$E45) -> 3 | H45: =SUMIFS('LANÇAMENTOS'!$H:$H,'LANÇAMENTOS'!$E:$E,"SAIDA",'LANÇAMENTOS'!$G:$G,$E45) -> 0 | J45: =I45*F45 -> 0
... D50: CABO | E50: RCA SUMAY 1,2M | F50: =G50-H50 -> 1 | G50: =SUMIFS('LANÇAMENTOS'!$H:$H,'LANÇAMENTOS'!$E:$E,"ENTRADA",'LANÇAMENTOS'!$G:$G,$E50) -> 4 | H50: =SUMIFS('LANÇAMENTOS'!$H:$H,'LANÇAMENTOS'!$E:$E,"SAIDA",'LANÇAMENTOS'!$G:$G,$E50) -> 3 | J50: =I50*F50 -> 0
D51: CAIXA DE SOM | E51: JBL CI6S PLUS | F51: =G51-H51 -> 0 | G51: =SUMIFS('LANÇAMENTOS'!$H:$H,'LANÇAMENTOS'!$E:$E,"ENTRADA",'LANÇAMENTOS'!$G:$G,$E51) -> 29 | H51: =SUMIFS('LANÇAMENTOS'!$H:$H,'LANÇAMENTOS'!$E:$E,"SAIDA",'LANÇAMENTOS'!$G:$G,$E51) -> 29 | I51: 228.74 | J51: =I51*F51 -> 0
D52: CAIXA DE SOM | E52: JBL CI6SA | F52: =G52-H52 -> 0 | G52: =SUMIFS('LANÇAMENTOS'!$H:$H,'LANÇAMENTOS'!$E:$E,"ENTRADA",'LANÇAMENTOS'!$G:$G,$E52) -> 1 | H52: =SUMIFS('LANÇAMENTOS'!$H:$H,'LANÇAMENTOS'!$E:$E,"SAIDA",'LANÇAMENTOS'!$G:$G,$E52) -> 1 | J52: =I52*F52 -> 0
D53: CAIXA DE SOM | E53: JBL CI6SA PLUS | F53: =G53-H53 -> 6 | G53: =SUMIFS('LANÇAMENTOS'!$H:$H,'LANÇAMENTOS'!$E:$E,"ENTRADA",'LANÇAMENTOS'!$G:$G,$E53) -> 27 | H53: =SUMIFS('LANÇAMENTOS'!$H:$H,'LANÇAMENTOS'!$E:$E,"SAIDA",'LANÇAMENTOS'!$G:$G,$E53) -> 21 | J53: =I53*F53 -> 0
D54: CAIXA DE SOM | E54: JBL CI8P | F54: =G54-H54 -> 8 | G54: =SUMIFS('LANÇAMENTOS'!$H:$H,'LANÇAMENTOS'!$E:$E,"ENTRADA",'LANÇAMENTOS'!$G:$G,$E54) -> 12 | H54: =SUMIFS('LANÇAMENTOS'!$H:$H,'LANÇAMENTOS'!$E:$E,"SAIDA",'LANÇAMENTOS'!$G:$G,$E54) -> 4 | I54: 664.73 | J54: =I54*F54 -> 5317.84
D55: CAIXA DE SOM | E55: JBL CI8S | F55: =G55-H55 -> 0 | G55: =SUMIFS('LANÇAMENTOS'!$H:$H,'LANÇAMENTOS'!$E:$E,"ENTRADA",'LANÇAMENTOS'!$G:$G,$E55) -> 4 | H55: =SUMIFS('LANÇAMENTOS'!$H:$H,'LANÇAMENTOS'!$E:$E,"SAIDA",'LANÇAMENTOS'!$G:$G,$E55) -> 4 | J55: =I55*F55 -> 0
D56: CAIXA DE SOM | E56: JBL CI8SA | F56: =G56-H56 -> 0 | G56: =SUMIFS('LANÇAMENTOS'!$H:$H,'LANÇAMENTOS'!$E:$E,"ENTRADA",'LANÇAMENTOS'!$G:$G,$E56) -> 3 | H56: =SUMIFS('LANÇAMENTOS'!$H:$H,'LANÇAMENTOS'!$E:$E,"SAIDA",'LANÇAMENTOS'!$G:$G,$E56) -> 3 | J56: =I56*F56 -> 0
...

Sheet LANÇAMENTOS
D1: DATA | E1: SITUAÇÃO | F1: TIPO | G1: PRODUTO | H1: QUANTIDADE
D6: DATA | E6: SITUAÇÃO | F6: TIPO | G6: PRODUTO | H6: QUANTIDADE
D8: 45763 | E8: SAIDA | F8: CLIENTE LOJA | G8: JBL CI6SA PLUS | H8: 4
D9: 45757 | E9: ENTRADA | F9: ACERTO ESTOQUE | G9: HDMI ARC | H9: 8
D10: 45757 | E10: ENTRADA | F10: ACERTO ESTOQUE | G10: SWITCH MERCURYS 5P FAST | H10: 1
D11: 45757 | E11: ENTRADA | F11: ACERTO ESTOQUE | G11: SWITCH MERCURYS 8P FAST | H11: 2
D12: 45757 | E12: ENTRADA | F12: ACERTO ESTOQUE | G12: SWITCH HIKVISION 5P 1GB | H12: 2
D13: 45757 | E13: ENTRADA | F13: ACERTO ESTOQUE | G13: SWITCH HIKVISION 8P 1GB | H13: 3
D14: 45757 | E14: SAIDA | F14: ACERTO ESTOQUE | G14: JBLMA510BLKBR | H14: 1
D15: 45757 | E15: SAIDA | F15: ACERTO ESTOQUE | G15: JBL CI6SA PLUS | H15: 3
D16: 45757 | E16: SAIDA | F16: ACERTO ESTOQUE | G16: JBL CI6S PLUS | H16: 2
D17: 45757 | E17: SAIDA | F17: ACERTO ESTOQUE | G17: RCA SUMAY 1,2M | H17: 3
D18: 45757 | E18: SAIDA | F18: ACERTO ESTOQUE | G18: FONTE 12V 3A | H18: 2
D19: 45757 | E19: ENTRADA | F19: ACERTO ESTOQUE | G19: RCA STORM 1M | H19: 10
... D168: 45521 | E168: ENTRADA | F168: ACERTO ESTOQUE | G168: TERMOSTATO | H168: 7

Sheet PEDIDO
B3: NOME COMPLETO:
B4: ENDEREÇO:
B5: TELEFONE:
B6: EMAIL:
E11: PEDIDO
B15: PRODUTOS | E15: QUANTIDADE | F15: PREÇO UNITÁRIO | H15: TOTAL
B16: Par de Caixa Som Ambiente JBL C321B 30W Branca | E16: 8 | F16: =626.1*2 -> 1252.2 | H16: =F16*E16 -> 10017.6
B17: Caixa Acústica Hayonik HSP-450IB Indoor Branca | E17: 16 | F17: =157.4*2 -> 314.8 | H17: =F17*E17 -> 5036.8
B60: INVESTIMENTO TOTAL | F60: =SUM(H15:H60) -> 15054.4
G67: Dados Bancarios
G69: PIX CNPJ: 13.744.082/0001-20
G70: AJUSTE FINO AUTOMAÇÃO RESIDENCIAL
A75: Rua Joinville, 36 | Vila Nova | Blumenau/SC
A76: (47) 3042 - 3781 | (47) 99139 - 6883
A77: www.ajustefinoht.com.br

Sheet PROD. SITE
A1: nome | B1: estoque-quantidade | C1: estoque-gerenciado | D1: estoque-situacao-em-estoque | E1: estoque-situacao-sem-estoque | F1: ativo | G1: usado | H1: id | I1: tipo | J1: sku-pai | K1: sku | L1: destaque | M1: ncm | N1: gtin | O1: mpn | P1: seo-tag-title | Q1: seo-tag-description | R1: descricao-completa | S1: url-video-youtube | T1: preco-sob-consulta | U1: preco-custo | V1: preco-cheio | W1: preco-promocional | X1: marca | Y1: peso-em-kg | Z1: altura-em-cm | AA1: largura-em-cm | AB1: comprimento-em-cm | AC1: categoria-nome-nivel-1 | AD1: categoria-nome-nivel-2 | AE1: categoria-nome-nivel-3 | AF1: categoria-nome-nivel-4 | AG1: categoria-nome-nivel-5 | AH1: imagem-1 | AI1: imagem-2 | AJ1: imagem-3 | AK1: imagem-4 | AL1: imagem-5 | AM1: grade-genero | AN1: grade-produto-com-uma-cor | AO1: grade-produto-com-duas-cores | AP1: grade-tamanho-de-anelalianca | AQ1: grade-tamanho-de-calca | AR1: grade-tamanho-de-camisacamiseta | AS1: grade-tamanho-de-capacete | AT1: grade-tamanho-de-tenis | AU1: grade-voltagem | AV1: grade-tamanho-juvenil-infantil | AW1: grade-formato-telacaixa-de-som | AX1: grade-formato-telacor | AY1: grade-tamanho-cabos | AZ1: grade-tamanho-de-projeto | BA1: grade-tamanho-mangueira
A2: Kit De Conector Banana Nakamichi 4 Unid | B2: 28 | C2: S | D2: imediata | E2: indisponivel | F2: S | G2: N | H2: 72473218 | I2: sem-variacao | K2: 2F7JN3U5D | L2: S | R2: <p><span style="font-size:16px;"><span style="font-family:trebuchet ms,helvetica,sans-serif;"><strong><span style="color: rgb(102, 102, 102);">DESCRIÇÃO:</span></strong><br style="box-sizing: border-box; color: rgb(102, 102, 102); font-family: &quot;Proxima Nova&quot;, -apple-system, &quot;Helvetica Neue&quot;, Helvetica, Roboto, Arial, sans-serif; font-size: 20px;" /> <span style="color: rgb(102, 102, 102);">Os conectores Nakamichi são fabricados com materiais de excelente qualidade, esse tipo de conector "BANANA" é muito utilizado na confecção de cabos de alta performance para sonorização de home theater e outros.</span><br style="box-sizing: border-box; color: rgb(102, 102, 102); font-family: &quot;Proxima Nova&quot;, -apple-system, &quot;Helvetica Neue&quot;, Helvetica, Roboto, Arial, sans-serif; font-size: 20px;" /> <br style="box-sizing: border-box; color: rgb(102, 102, 102); font-family: &quot;Proxima Nova&quot;, -apple-system, &quot;Helvetica Neue&quot;, Helvetica, Roboto, Arial, sans-serif; font-size: 20px;" /> <strong><span style="color: rgb(102, 102, 102);">ESPECIFICAÇÃO:</span></strong><br style="box-sizing: border-box; color: rgb(102, 102, 102); font-family: &quot;Proxima Nova&quot;, -apple-system, &quot;Helvetica Neue&quot;, Helvetica, Roboto, Arial, sans-serif; font-size: 20px;" /> <span style="color: rgb(102, 102, 102);">- Alta qualidade 100% novo!</span><br style="box-sizing: border-box; color: rgb(102, 102, 102); font-family: &quot;Proxima Nova&quot;, -apple-system, &quot;Helvetica Neue&quot;, Helvetica, Roboto, Arial, sans-serif; font-size: 20px;" /> <span style="color: rgb(102, 102, 102);">- Chapeamento de ouro 24k para transferência de sinal máximo e durabilidade.</span><br style="box-sizing: border-box; color: rgb(102, 102, 102); font-family: &quot;Proxima Nova&quot;, -apple-system, &quot;Helvetica Neue&quot;, Helvetica, Roboto, Arial, sans-serif; font-size: 20px;" /> <span style="color: rgb(102, 102, 102);">- Acomoda o cabo com tamanho do fio até 4mm. Aceita 8awg ao fio do orador 20awg.</span><br style="box-sizing: border-box; color: rgb(102, 102, 102); font-family: &quot;Proxima Nova&quot;, -apple-system, &quot;Helvetica Neue&quot;, Helvetica, Roboto, Arial, sans-serif; font-size: 20px;" /> <span style="color: rgb(102, 102, 102);">- Parafusos dobro de travamento.</span><br style="box-sizing: border-box; color: rgb(102, 102, 102); font-family: &quot;Proxima Nova&quot;, -apple-system, &quot;Helvetica Neue&quot;, Helvetica, Roboto, Arial, sans-serif; font-size: 20px;" /> <span style="color: rgb(102, 102, 102);">- Kit com 04 unidades sendo 02 vermelhas e 02 pretas.</span></span></span></p> | T2: N | V2: 43.9 | X2: Nakamichi | Y2: 0.4 | Z2: 20 | AA2: 20 | AB2: 10 | AH2: https://cdn.awsli.com.br/948/948321/produto/72473218/83d46b23c8.jpg | AI2: https://cdn.awsli.com.br/948/948321/produto/72473218/2cedede271.jpg
A3: CABO DE ÁUDIO ÓPTICO TOSLINK PIX 2m | B3: 21 | C3: S | D3: imediata | E3: indisponivel | F3: S | G3: N | H3: 59336047 | I3: sem-variacao | K3: TOSLINK2M | L3: N | R3: <p><span style="font-size:16px;"><span style="font-family:verdana,geneva,sans-serif;">Você merece o melhor som digital e sem nenhum tipo de interferências ou distorção!</span></span></p> <p><span style="font-size:16px;"><span style="font-family:verdana,geneva,sans-serif;">Aproveite o máximo de fidelidade e desempenho sonoro dos seus equipamentos com o Cabo Ótico Digital da CHIP SCE. Com ele você poderá ter uma transmissão livre de interferências e qualidade incomparável de áudio.</span></span></p> <p><span style="font-size:16px;"><span style="font-family:verdana,geneva,sans-serif;">Indicado para equipamentos que utilizam conexão óptica como: Blu-ray, TV's, receptores de TV Digital, vídeo games, receivers, DVD, home theaters e demais equipamentos que se adéquam à este sistema.</span></span></p> <p><span style="font-size:16px;"><strong><span style="font-family:verdana,geneva,sans-serif;">Especificações Técnicas:</span></strong></span></p> <p><span style="font-size:16px;"><span style="font-family:verdana,geneva,sans-serif;">Tamanho: 02 metros</span></span></p> <p><span style="font-size:16px;"><span style="font-family:verdana,geneva,sans-serif;">Conectores: Toslink - Gold</span></span></p> <p><span style="font-size:16px;"><span style="font-family:verdana,geneva,sans-serif;">Cabo: Fibra Ótica</span></span></p> <p><span style="font-size:16px;"><span style="font-family:verdana,geneva,sans-serif;">Aplicações: Blu-Ray, Receptores de Imagens digitais, Vídeo Games, Receivers, DVD, TVs e Home Theater.</span></span></p> <p><span style="font-size:16px;"><span style="font-family:verdana,geneva,sans-serif;"><strong>Conteúdo da embalagem:</strong><br /> 01 - Cabo Ótico de 2 metros</span></span></p> | T3: N | V3: 19.99 | X3: PIX | Y3: 0.8 | Z3: 12 | AA3: 12 | AB3: 12 | AH3: https://cdn.awsli.com.br/948/948321/produto/59336047/82a8782820.jpg | AI3: https://cdn.awsli.com.br/948/948321/produto/59336047/61c4b17699.jpg
